# CH10.Error Handling

오류처리 구문이란 프로그램이 오류를 일으켰을 때 타입이나 코드의 흐름과 상관없이 오류를 던질 수 있도록 하는 구문이다. 

오류 처리 구문에서는 다양한 오류들을 합수 외부로 전달 하는것이 가능하다.

오류는 반환하는것이 아니라 던지는 처리를 할 수 있게끔 지원한다.

## Contents

- [A. Basic](https://github.com/TheSwifters/iOS-Study/blob/master/Swift/CH10.ErrorHandling.md#a-basic)
- [B. NSError](https://github.com/TheSwifters/iOS-Study/blob/master/Swift/CH10.ErrorHandling.md#b-nserror)
- [C. defer](https://github.com/TheSwifters/iOS-Study/blob/master/Swift/CH10.ErrorHandling.md#c-defer)
- [D. Result](https://github.com/TheSwifters/iOS-Study/blob/master/Swift/CH10.ErrorHandling.md#d-result)



## A. Basic

- 오류 타입 정의

  - 오류 처리를 위해서는 오류 정보를 담아 함수나 메소드 외부로 던질 오류 타입 객체가 필요함.

  - 컴파일러는 Error 프로토콜을 준수하는 타입만을 오류 타입으로 인정한다. (enum, class, struct 등)

    ```swift
    // 회원가입시 입력받은 아이디가 사용 가능한 아이디인지 체크하는 에러 타입 정의
    // 여기서는 간단하게 문자열의 길이와 중복체크만 한다
    enum SignUpError: Error {
        case overSizeString
        // 입력된 문자열의 길이가 정해진 크기보다 큰 경우
        case underSizeString
        // 입력된 문자열의 길이가 정해진 크기보다 부족한 경우
        case overlappingAccount
        // 중복된 아이디인 경우
    }
    ```

- 오류 던지기

  - 오류를 던지는 함수에서는 return 타입 앞에 throws를 붙여준다.

  - throws를 붙인 함수내에서는 error 발생시 throw를 통해 함수 밖으로 던진다.

    ```swift
    // 사용가능한 아이디의 조건
    // 1. 4 ~ 8자의 아이디 사용
    // 2. 중복되지 않는 아이디 사용
    // 위 조건을 만족하지 않을경우 해당하는 error를 throw 하고,
    // 위 조건을 모두 만족할 경우 id를 다시 리턴해 준다. (암호화등의 과정을 거친다고 가정함.)
    func checkID(id: String) throws -> String {
        guard id.count < 9 else { throw SignUpError.overSizeString }
        guard id.count > 3 else { throw SignUpError.underSizeString }
        guard !userIDs.contains(id) else { throw SignUpError.overlappingAccount }
        return id
    }
    ```

    

- 오류 처리하기

  오류 처리에는 try, try?, try! 세가지방법이 있다.

  - try

    try는 do...catch 구문 안에서 사용하며 error발생시 catch 구문에서 처리한다.

    ```swift
    var userIDs: [String] = []
    // userIDs 배열을 데이터베이스라고 가정
    
    // signUp 함수를 try 호출 하고 error 발생시 catch구문에서 error를 잡아서 처리한다.
    // 함수가 정상적으로 완료되면 userIDs배열에 append 한다.
    do {
        let id = try checkID(id: "JoongChag")
        userIDs.append(id)
    } catch SignUpError.overSizeString {
        print("8자 이하의 아이디를 사용해 주세요.")
    } catch SignUpError.underSizeString {
        print("4자 이상의 아이디를 사용해 주세요")
    } catch SignUpError.overlappingAccount {
        print("중복된 아이디 입니다.")
    }
    print(userIDs)
    // 실행 결과 -> 8자 이하의 아이디를 사용해 주세요.
    // userIDs -> []
    ```

  - try?

    try?는 함수 실행간에 error가 발생하게 되면 nil을 반환한다.

    따라서 함수 에서 return 받는 타입은 옵셔널이다.

    ```swift
    let id = try? signUp(id: "JoongChag") // nil
    ```

  - try!

    try!는 옵셔널 강제 언래핑과 같이 옵셔널이 벗겨진 상태로 반환한다. 

    하지만 실패하게되면 애플리케이션 크래쉬가 발생하기 때문에 반드시 성공한다는 확신이 있을 경우에만 사용해야 한다.
    
    ```swift
    let id = try! signUp(id: "JoongChag") // Fatal error
    ```



## B. NSError

```swift
func throwNSError() throws {
  // NSError() - 기본 생성자 (X),  Domain cannot be nil
  throw NSError(domain: "Domain error string", code: 99, userInfo: ["MyKey": "MyValue"])
}

func throwsNSErrorExample() {
  do {
    try throwNSError()
  } catch {
    print("Error :", error)
    
    let e = error as NSError
    print("NSError :", e)
    print("domain :", e.domain)
    print("code :", e.code)
    print("userInfo :", e.userInfo)
  }
}

throwsNSErrorExample()
/*
 실행 결과
 Error : Error Domain=Domain error string Code=99 "(null)" UserInfo={MyKey=MyValue}
 NSError : Error Domain=Domain error string Code=99 "(null)" UserInfo={MyKey=MyValue}
 domain : Domain error string
 code : 99
 userInfo : ["MyKey": "MyValue"]

 */

```



## C. defer

defer 구문은 현재 진행중인 코드블럭에서 실행 흐름이 벗어나는 시점에 수행해야할 작업을 지정할 수 있다.

defer 구문은 return 이나 break 또는 예외로 인해 강제로 벗어나는 경우에도 동작한다.

```swift
func deferTest() {
    defer {
        print("Finished function")
    }
    print("Start function")
}

deferTest()
/*
 실행 결과
 Start function
 Finished function
 */

```



## D. Result

Result는 제네릭을 사용한 enum이다.

Failure는 Error protocol을 채택하고 있기 때문에 Error 프로토콜을 채택하는 타입은 모두 들어갈 수 있다.

success와 failure 두개의 case가 있으며 map, flatmap등등 여러가지 함수들이 있다.

```swift
enum Result<Success, Failure> where Failure : Error {
  case success(Success)
  case failure(Failure)
  //functions ...
}
```

- 에러 정의

  ```swift
  // 회원가입시 입력받은 아이디가 사용 가능한 아이디인지 체크하는 에러 타입 정의
  // 여기서는 간단하게 문자열의 길이와 중복체크만 한다
  enum SignUpError: Error {
      case overSizeString
      // 입력된 문자열의 길이가 정해진 크기보다 큰 경우
      case underSizeString
      // 입력된 문자열의 길이가 정해진 크기보다 부족한 경우
      case overlappingAccount
      // 중복된 아이디인 경우
  }
  ```

- 함수 정의

  ```swift
  var userIDs: [String] = ["Joong"]
  // userIDs 배열을 데이터베이스라고 가정
  
  // 사용가능한 아이디의 조건
  // 1. 4 ~ 8자의 아이디 사용
  // 2. 중복되지 않는 아이디 사용
  // 위 조건을 만족하지 않을경우 completionHandler에 failure case로 error를 매개변수로 넣어 호출하고 함수 종료,
  // 위 조건을 모두 만족할 경우 completionHandler에 success case로 id를 매개변수로 넣어 호출한다.
  func signUP(id: String, completionHandler: (Result<String, SignUpError>) -> Void) {
      guard id.count < 9 else {
          completionHandler(.failure(.overSizeString))
          return
      }
      guard id.count > 3 else {
          completionHandler(.failure(.underSizeString))
          return
      }
      guard !userIDs.contains(id) else {
          completionHandler(.failure(.overlappingAccount))
          return
      }
      completionHandler(.success(id))
  }
  ```

- 함수 호출

  ```swift
  signUP(id: "Joong", completionHandler: {
      (result: Result<String, SignUpError>) in
      
      switch result {
      case .success(let id):
          userIDs.append(id)
      case .failure(let error):
          print(error)
      }
      
  })
  
  print("userIDs:", userIDs)
  /*
  실행 결과
  overlappingAccount
  userIDs: ["Joong"]
  */
  ```

